<?xml version="1.0" encoding="UTF-8"?>
<testsuites name="Mocha Tests" time="1.528" tests="1" failures="1">
  <testsuite name="Root Suite" timestamp="2025-09-12T10:59:35" tests="0" file="cypress/e2e/smoke-avi-lab.cy.ts" time="0.000" failures="0">
  </testsuite>
  <testsuite name="AVI_LAB – Toggles and Basic Flow (smoke)" timestamp="2025-09-12T10:59:35" tests="1" time="1.486" failures="2">
    <testcase name="AVI_LAB – Toggles and Basic Flow (smoke) &quot;before each&quot; hook for &quot;shows Questions tab, lexicon toggles and Basic Info Flow&quot;" time="0.115" classname="&quot;before each&quot; hook for &quot;shows Questions tab, lexicon toggles and Basic Info Flow&quot;">
      <failure message="An error was thrown while processing a network event: A fixture file could not be found at any of the following paths:

    &gt; cypress/fixtures/quote-created.json
    &gt; cypress/fixtures/quote-created.json.[ext]

Cypress looked for these file extensions at the provided path:

    &gt; .json, .js, .coffee, .html, .txt, .csv, .png, .jpg, .jpeg, .gif, .tif, .tiff, .zip

Provide a path to an existing fixture file.

Because this error occurred during a `before each` hook we are skipping all of the remaining tests." type="Error"><![CDATA[Error: An error was thrown while processing a network event: A fixture file could not be found at any of the following paths:

    > cypress/fixtures/quote-created.json
    > cypress/fixtures/quote-created.json.[ext]

Cypress looked for these file extensions at the provided path:

    > .json, .js, .coffee, .html, .txt, .csv, .png, .jpg, .jpeg, .gif, .tif, .tiff, .zip

Provide a path to an existing fixture file.

Because this error occurred during a `before each` hook we are skipping all of the remaining tests.
    at Object.<anonymous> (<embedded>:2521:322389)
    at Object.tryCatcher (/Users/josuehernandez/Library/Caches/Cypress/15.0.0/Cypress.app/Contents/Resources/app/node_modules/bluebird/js/release/util.js:16:23)
    at Promise._settlePromiseFromHandler (/Users/josuehernandez/Library/Caches/Cypress/15.0.0/Cypress.app/Contents/Resources/app/node_modules/bluebird/js/release/promise.js:512:31)
    at Promise._settlePromise (/Users/josuehernandez/Library/Caches/Cypress/15.0.0/Cypress.app/Contents/Resources/app/node_modules/bluebird/js/release/promise.js:569:18)
    at Promise._settlePromise0 (/Users/josuehernandez/Library/Caches/Cypress/15.0.0/Cypress.app/Contents/Resources/app/node_modules/bluebird/js/release/promise.js:614:10)
    at Promise._settlePromises (/Users/josuehernandez/Library/Caches/Cypress/15.0.0/Cypress.app/Contents/Resources/app/node_modules/bluebird/js/release/promise.js:694:18)
    at Promise._fulfill (/Users/josuehernandez/Library/Caches/Cypress/15.0.0/Cypress.app/Contents/Resources/app/node_modules/bluebird/js/release/promise.js:638:18)
    at <unknown> (/Users/josuehernandez/Library/Caches/Cypress/15.0.0/Cypress.app/Contents/Resources/app/node_modules/bluebird/js/release/nodeback.js:42:21)
    at s (<embedded>:227:108639)
    at D.<anonymous> (<embedded>:2515:170857)
    at D.emit (node:events:518:28)
    at D._finish (<embedded>:2515:171787)
    at i (<embedded>:2515:171178)
    at D._processSimple2 (<embedded>:2515:176944)
    at <unknown> (<embedded>:2515:176797)
    at D._stat2 (<embedded>:2515:177862)
    at <unknown> (<embedded>:2515:177709)
    at s (<embedded>:1072:24225)
    at s (<embedded>:227:108639)
    at r (<embedded>:2586:13639)
    at FSReqCallback.oncomplete (node:fs:198:21)]]></failure>
    </testcase>
    <testcase name="AVI_LAB – Toggles and Basic Flow (smoke) &quot;after all&quot; hook: generateReport for &quot;shows Questions tab, lexicon toggles and Basic Info Flow&quot;" time="0.115" classname="&quot;after all&quot; hook: generateReport for &quot;shows Questions tab, lexicon toggles and Basic Info Flow&quot;">
      <failure message="`cy.task(&apos;coverageReport&apos;)` failed with the following error:

&gt; Command failed with exit code 1: npm run coverage:report

https://on.cypress.io/api/task

Because this error occurred during a `after all` hook we are skipping all of the remaining tests.

Although you have test retries enabled, we do not retry tests when `before all` or `after all` hooks fail" type="CypressError"><![CDATA[CypressError: `cy.task('coverageReport')` failed with the following error:

> Command failed with exit code 1: npm run coverage:report

https://on.cypress.io/api/task

Because this error occurred during a `after all` hook we are skipping all of the remaining tests.

Although you have test retries enabled, we do not retry tests when `before all` or `after all` hooks fail
    at <unknown> (http://localhost:8080/__cypress/runner/cypress_runner.js:138627:70)
    at tryCatcher (http://localhost:8080/__cypress/runner/cypress_runner.js:1777:23)
    at Promise._settlePromiseFromHandler (http://localhost:8080/__cypress/runner/cypress_runner.js:1489:31)
    at Promise._settlePromise (http://localhost:8080/__cypress/runner/cypress_runner.js:1546:18)
    at Promise._settlePromise0 (http://localhost:8080/__cypress/runner/cypress_runner.js:1591:10)
    at Promise._settlePromises (http://localhost:8080/__cypress/runner/cypress_runner.js:1667:18)
    at _drainQueueStep (http://localhost:8080/__cypress/runner/cypress_runner.js:2377:12)
    at _drainQueue (http://localhost:8080/__cypress/runner/cypress_runner.js:2370:9)
    at Async._drainQueues (http://localhost:8080/__cypress/runner/cypress_runner.js:2386:5)
    at Async.drainQueues (http://localhost:8080/__cypress/runner/cypress_runner.js:2256:14)
From Your Spec Code:
    at Context.generateReport (webpack://conductores-pwa/./node_modules/@cypress/code-coverage/support.js:263:0)

From Node.js Internals:
  Error: Command failed with exit code 1: npm run coverage:report
      at makeError (/Users/josuehernandez/pwa_angular/node_modules/@cypress/code-coverage/node_modules/execa/lib/error.js:59:11)
      at handlePromise (/Users/josuehernandez/pwa_angular/node_modules/@cypress/code-coverage/node_modules/execa/index.js:114:26)
      at process.processTicksAndRejections (node:internal/process/task_queues:105:5)]]></failure>
    </testcase>
  </testsuite>
</testsuites>